Workbook

Sheet Instructions
A1: FantasyIQ Trust
A2: Dynamic Trade Value Chart Engine
A3: Commissioner-Grade Fantasy Football Trade Evaluation Tool
A5: Welcome to FantasyIQ Trust!
A6: This proprietary valuation engine helps commissioners and league managers evaluate fantasy football trades using a dynamic,
A7: multi-factor scoring model. Configure your league, review player values, adjust weighted factors, and evaluate trades with precision.
A9: TAB OVERVIEW
A11: Tab | B11: Description
A12: League Settings | B12: The input hub where commissioners configure their league format, roster settings, scoring, and trade deadline.
A13: Base Player Values | B13: 60 pre-loaded NFL players with raw base values on a 0–100 scale across QB, RB, WR, TE, K, and DEF.
A14: Dynamic Adjustments | B14: 6 weighted adjustment factors (summing to 1.0) that modify base values: Position Scarcity, Age Curve, Recent Performance, Schedule Strength, Injury Risk, and Team Situation.
A15: Dynamic Trade Chart | B15: The core DTV formula engine that computes Final Adjusted Dynamic Trade Values for all 60 players using the weighted factor model.
A16: Trade Calculator | B16: Evaluate trades up to 5 vs 5 players with automatic 0-100 Trade Scores and verdicts.
A18: TRADE SCORING SYSTEM (0–100)
A19: Score Range | B19: Verdict | C19: Meaning
A20: 90 – 100 | B20: Slam Dunk | C20: Massive win for Team A
A21: 75 – 89 | B21: Strong Win | C21: Clear win for Team A
A22: 60 – 74 | B22: Slight Edge | C22: Slight edge to Team A
A23: 45 – 59 | B23: Fair Trade | C23: Fair / Even trade
A24: 30 – 44 | B24: Slight Loss | C24: Slight edge to Team B
A25: 15 – 29 | B25: Bad Deal | C25: Clear win for Team B
A26: 0 – 14 | B26: Robbery | C26: Massive win for Team B
A28: DTV TIER LABELS
A29: Tier | B29: DTV Range | C29: Color
A30: Elite | B30: ≥ 85 | C30: Gold
A31: Star | B31: 70 – 84 | C31: Green
A32: Starter | B32: 55 – 69 | C32: Blue
A33: Flex | B33: 40 – 54 | C33: Gray
A34: Bench | B34: 25 – 39 | C34: Orange
A35: Waiver | B35: < 25 | C35: Red
A37: LEAGUE TYPE TOGGLE (NEW)
B38: Feature | C38: Description
B39: League Type Setting | C39: Located in League Settings tab (B19). Dropdown with two options: "Redraft" or "Dynasty". Default is Redraft.
B40: Redraft Mode | C40: All players receive an Active Age Curve of 1.0 — age has no impact on trade values. Best for single-season leagues.
B41: Dynasty Mode | C41: Players use the full age curve multiplier: ≤24 = 1.15, 25–27 = 1.05, 28–30 = 0.95, ≥31 = 0.85. Young players gain value; older players lose value.
B42: How It Works | C42: The "Active Age Curve" column (Q) in the Dynamic Trade Chart reads the League Type setting and applies the appropriate multiplier. The Raw DTV formula uses Active Age Curve instead of the raw Age Multiplier.
A44: RECENT PERFORMANCE FACTOR (PHASE 2 PLACEHOLDER)
B45: Feature | C45: Description
B46: Recent Perf Factor | C46: Column R in the Dynamic Trade Chart. Currently set to 1.0 for all players (no effect). Placeholder for Phase 2 live stats integration.
B47: Phase 2 Plan | C47: Will be powered by a live stats API to automatically adjust trade values based on recent player performance trends (last 4 weeks).
...

Sheet League Settings
A1: League Settings — Input Hub
A2: Configure your league parameters below. These settings feed into the Dynamic Trade Chart calculations.
A4: Setting | B4: Value | D4: Notes
A5: League Name | B5: My League | D5: Enter your league name
A6: Scoring Format | B6: Half PPR | D6: Standard / Half PPR / Full PPR
A7: PPR Reception Points | B7: 0.5 | D7: Auto: 0=Std, 0.5=Half, 1.0=Full
A8: Number of Teams | B8: 12 | D8: 8 / 10 / 12 / 14 / 16 / 32
A9: Roster Size | B9: 15 | D9: Total roster spots
A10: QB Slots | B10: 1 | D10: Quarterback slots
A11: RB Slots | B11: 2 | D11: Running back slots
A12: WR Slots | B12: 2 | D12: Wide receiver slots
A13: TE Slots | B13: 1 | D13: Tight end slots
A14: FLEX Slots | B14: 1 | D14: FLEX (RB/WR/TE) slots
A15: K Slots | B15: 1 | D15: Kicker slots
A16: DEF Slots | B16: 1 | D16: Defense/ST slots
A17: Trade Deadline Week | B17: 10 | D17: NFL week trade deadline
A18: Waiver Type | B18: FAAB | D18: FAAB / Rolling / Reverse Standings
A19: League Type | B19: Redraft | D19: Redraft = age-neutral (1.0); Dynasty = full age curve

Sheet Base Player Values
A1: Base Player Values
A2: 60 Pre-Loaded NFL Players — Raw Base Values (0–100 Scale)
A3: Rank | B3: Player Name | C3: Position | D3: Team | E3: Age | F3: Base Value
A4: 1 | B4: Ja'Marr Chase | C4: WR | D4: CIN | E4: 25 | F4: 97
A5: 2 | B5: Bijan Robinson | C5: RB | D5: ATL | E5: 23 | F5: 96
A6: 3 | B6: Josh Allen | C6: QB | D6: BUF | E6: 30 | F6: 95
A7: 4 | B7: CeeDee Lamb | C7: WR | D7: DAL | E7: 26 | F7: 95
A8: 5 | B8: Breece Hall | C8: RB | D8: NYJ | E8: 24 | F8: 93
A9: 6 | B9: Lamar Jackson | C9: QB | D9: BAL | E9: 29 | F9: 93
A10: 7 | B10: Jahmyr Gibbs | C10: RB | D10: DET | E10: 23 | F10: 92
A11: 8 | B11: Tyreek Hill | C11: WR | D11: MIA | E11: 32 | F11: 91
A12: 9 | B12: Amon-Ra St. Brown | C12: WR | D12: DET | E12: 25 | F12: 91
A13: 10 | B13: Saquon Barkley | C13: RB | D13: PHI | E13: 28 | F13: 90
A14: 11 | B14: Patrick Mahomes | C14: QB | D14: KC | E14: 30 | F14: 90
A15: 12 | B15: Puka Nacua | C15: WR | D15: LAR | E15: 24 | F15: 89
... A63: 60 | B63: Jake Moody | C63: K | D63: SF | E63: 26 | F63: 38

Sheet Dynamic Adjustments
A1: Dynamic Adjustments
A2: 6 Weighted Adjustment Factors — Must Sum to 1.0
A4: Factor | B4: Weight | C4: Description
A5: Position Scarcity | B5: 0.25 | C5: Multipliers by position: QB 0.95, RB 1.25, WR 1.20, TE 1.10, K 0.85, DEF 0.85
A6: Age Curve | B6: 0.2 | C6: Multipliers by age: ≤24=1.15, 25–27=1.05, 28–30=0.95, ≥31=0.85
A7: Recent Performance | B7: 0.2 | C7: Last 4 weeks trend modifier (user input per player, scale 0.80–1.20)
A8: Schedule Strength | B8: 0.15 | C8: Remaining schedule difficulty (user input per player, scale 0.85–1.15)
A9: Injury Risk | B9: 0.1 | C9: Health/durability factor (user input per player, scale 0.70–1.10)
A10: Team Situation | B10: 0.1 | C10: Coaching, offensive scheme, target share context (user input per player, scale 0.80–1.20)
A12: Weight Total | B12: =SUM(B5:B10)
A13: Validation | C13: =IF(B12=1,"VALID ✔ Weights sum to 1.0","WARNING ⚠ Weights do NOT sum to 1.0!")
A16: Position Scarcity Multiplier Table
A17: Position | B17: Multiplier
A18: QB | B18: 0.95
A19: RB | B19: 1.25
A20: WR | B20: 1.2
A21: TE | B21: 1.1
A22: K | B22: 0.85
A23: DEF | B23: 0.85
A26: Age Curve Multiplier Table
A27: Age Range | B27: Multiplier
A28: ≤ 24 | B28: 1.15
A29: 25 – 27 | B29: 1.05
A30: 28 – 30 | B30: 0.95
A31: ≥ 31 | B31: 0.85

Sheet Dynamic Trade Chart
A1: Dynamic Trade Chart — Core DTV Engine
A2: Final Adjusted Dynamic Trade Values — Computed from Base Values × Weighted Factor Model
A3: Rank | B3: Player Name | C3: Position | D3: Age | E3: Base Value | F3: Pos Multiplier | G3: Age Multiplier | H3: Perf Factor | I3: Sched Factor | J3: Injury Factor | K3: Situation Factor | L3: Raw DTV | M3: PPR Boost | N3: Final Adj DTV | O3: DTV Tier | P3: Catch Rate | Q3: Active Age Curve | R3: Recent Perf Factor
A4: 1 | B4: ='Base Player Values'!B4 | C4: ='Base Player Values'!C4 | D4: ='Base Player Values'!E4 | E4: ='Base Player Values'!F4 | F4: =IFERROR(VLOOKUP(C4,'Dynamic Adjustments'!$A$18:$B$23,2,FALSE),1) | G4: =IF(OR(C4="DEF",C4="K",D4=0),1,IF(D4<=24,'Dynamic Adjustments'!$B$28,IF(D4<=27,'Dynamic Adjustments'!$B$29,IF(D4<=30,'Dynamic Adjustments'!$B$30,'Dynamic Adjustments'!$B$31)))) | H4: 1 | I4: 1 | J4: 1 | K4: 1 | L4: =E4*('Dynamic Adjustments'!$B$5*F4+'Dynamic Adjustments'!$B$6*Q4+'Dynamic Adjustments'!$B$7*H4+'Dynamic Adjustments'!$B$8*I4+'Dynamic Adjustments'!$B$9*J4+'Dynamic Adjustments'!$B$10*K4) | M4: =P4*'League Settings'!$B$7 | N4: =(L4+M4)*R4 | O4: =IF(N4>=85,"Elite",IF(N4>=70,"Star",IF(N4>=55,"Starter",IF(N4>=40,"Flex",IF(N4>=25,"Bench","Waiver"))))) | P4: =IF(C4="WR",1,IF(C4="TE",0.8,IF(C4="RB",0.5,0))) | Q4: =IF('League Settings'!$B$19="Redraft",1,IF(OR(C4="DEF",C4="K",D4=0),1,IF(D4<=24,'Dynamic Adjustments'!$B$28,IF(D4<=27,'Dynamic Adjustments'!$B$29,IF(D4<=30,'Dynamic Adjustments'!$B$30,'Dynamic Adjustments'!$B$31))))) | R4: 1
A5: 2 | B5: ='Base Player Values'!B5 | C5: ='Base Player Values'!C5 | D5: ='Base Player Values'!E5 | E5: ='Base Player Values'!F5 | F5: =IFERROR(VLOOKUP(C5,'Dynamic Adjustments'!$A$18:$B$23,2,FALSE),1) | G5: =IF(OR(C5="DEF",C5="K",D5=0),1,IF(D5<=24,'Dynamic Adjustments'!$B$28,IF(D5<=27,'Dynamic Adjustments'!$B$29,IF(D5<=30,'Dynamic Adjustments'!$B$30,'Dynamic Adjustments'!$B$31)))) | H5: 1 | I5: 1 | J5: 1 | K5: 1 | L5: =E5*('Dynamic Adjustments'!$B$5*F5+'Dynamic Adjustments'!$B$6*Q5+'Dynamic Adjustments'!$B$7*H5+'Dynamic Adjustments'!$B$8*I5+'Dynamic Adjustments'!$B$9*J5+'Dynamic Adjustments'!$B$10*K5) | M5: =P5*'League Settings'!$B$7 | N5: =(L5+M5)*R5 | O5: =IF(N5>=85,"Elite",IF(N5>=70,"Star",IF(N5>=55,"Starter",IF(N5>=40,"Flex",IF(N5>=25,"Bench","Waiver"))))) | P5: =IF(C5="WR",1,IF(C5="TE",0.8,IF(C5="RB",0.5,0))) | Q5: =IF('League Settings'!$B$19="Redraft",1,IF(OR(C5="DEF",C5="K",D5=0),1,IF(D5<=24,'Dynamic Adjustments'!$B$28,IF(D5<=27,'Dynamic Adjustments'!$B$29,IF(D5<=30,'Dynamic Adjustments'!$B$30,'Dynamic Adjustments'!$B$31))))) | R5: 1
A6: 3 | B6: ='Base Player Values'!B6 | C6: ='Base Player Values'!C6 | D6: ='Base Player Values'!E6 | E6: ='Base Player Values'!F6 | F6: =IFERROR(VLOOKUP(C6,'Dynamic Adjustments'!$A$18:$B$23,2,FALSE),1) | G6: =IF(OR(C6="DEF",C6="K",D6=0),1,IF(D6<=24,'Dynamic Adjustments'!$B$28,IF(D6<=27,'Dynamic Adjustments'!$B$29,IF(D6<=30,'Dynamic Adjustments'!$B$30,'Dynamic Adjustments'!$B$31)))) | H6: 1 | I6: 1 | J6: 1 | K6: 1 | L6: =E6*('Dynamic Adjustments'!$B$5*F6+'Dynamic Adjustments'!$B$6*Q6+'Dynamic Adjustments'!$B$7*H6+'Dynamic Adjustments'!$B$8*I6+'Dynamic Adjustments'!$B$9*J6+'Dynamic Adjustments'!$B$10*K6) | M6: =P6*'League Settings'!$B$7 | N6: =(L6+M6)*R6 | O6: =IF(N6>=85,"Elite",IF(N6>=70,"Star",IF(N6>=55,"Starter",IF(N6>=40,"Flex",IF(N6>=25,"Bench","Waiver"))))) | P6: =IF(C6="WR",1,IF(C6="TE",0.8,IF(C6="RB",0.5,0))) | Q6: =IF('League Settings'!$B$19="Redraft",1,IF(OR(C6="DEF",C6="K",D6=0),1,IF(D6<=24,'Dynamic Adjustments'!$B$28,IF(D6<=27,'Dynamic Adjustments'!$B$29,IF(D6<=30,'Dynamic Adjustments'!$B$30,'Dynamic Adjustments'!$B$31))))) | R6: 1
A7: 4 | B7: ='Base Player Values'!B7 | C7: ='Base Player Values'!C7 | D7: ='Base Player Values'!E7 | E7: ='Base Player Values'!F7 | F7: =IFERROR(VLOOKUP(C7,'Dynamic Adjustments'!$A$18:$B$23,2,FALSE),1) | G7: =IF(OR(C7="DEF",C7="K",D7=0),1,IF(D7<=24,'Dynamic Adjustments'!$B$28,IF(D7<=27,'Dynamic Adjustments'!$B$29,IF(D7<=30,'Dynamic Adjustments'!$B$30,'Dynamic Adjustments'!$B$31)))) | H7: 1 | I7: 1 | J7: 1 | K7: 1 | L7: =E7*('Dynamic Adjustments'!$B$5*F7+'Dynamic Adjustments'!$B$6*Q7+'Dynamic Adjustments'!$B$7*H7+'Dynamic Adjustments'!$B$8*I7+'Dynamic Adjustments'!$B$9*J7+'Dynamic Adjustments'!$B$10*K7) | M7: =P7*'League Settings'!$B$7 | N7: =(L7+M7)*R7 | O7: =IF(N7>=85,"Elite",IF(N7>=70,"Star",IF(N7>=55,"Starter",IF(N7>=40,"Flex",IF(N7>=25,"Bench","Waiver"))))) | P7: =IF(C7="WR",1,IF(C7="TE",0.8,IF(C7="RB",0.5,0))) | Q7: =IF('League Settings'!$B$19="Redraft",1,IF(OR(C7="DEF",C7="K",D7=0),1,IF(D7<=24,'Dynamic Adjustments'!$B$28,IF(D7<=27,'Dynamic Adjustments'!$B$29,IF(D7<=30,'Dynamic Adjustments'!$B$30,'Dynamic Adjustments'!$B$31))))) | R7: 1
A8: 5 | B8: ='Base Player Values'!B8 | C8: ='Base Player Values'!C8 | D8: ='Base Player Values'!E8 | E8: ='Base Player Values'!F8 | F8: =IFERROR(VLOOKUP(C8,'Dynamic Adjustments'!$A$18:$B$23,2,FALSE),1) | G8: =IF(OR(C8="DEF",C8="K",D8=0),1,IF(D8<=24,'Dynamic Adjustments'!$B$28,IF(D8<=27,'Dynamic Adjustments'!$B$29,IF(D8<=30,'Dynamic Adjustments'!$B$30,'Dynamic Adjustments'!$B$31)))) | H8: 1 | I8: 1 | J8: 1 | K8: 1 | L8: =E8*('Dynamic Adjustments'!$B$5*F8+'Dynamic Adjustments'!$B$6*Q8+'Dynamic Adjustments'!$B$7*H8+'Dynamic Adjustments'!$B$8*I8+'Dynamic Adjustments'!$B$9*J8+'Dynamic Adjustments'!$B$10*K8) | M8: =P8*'League Settings'!$B$7 | N8: =(L8+M8)*R8 | O8: =IF(N8>=85,"Elite",IF(N8>=70,"Star",IF(N8>=55,"Starter",IF(N8>=40,"Flex",IF(N8>=25,"Bench","Waiver"))))) | P8: =IF(C8="WR",1,IF(C8="TE",0.8,IF(C8="RB",0.5,0))) | Q8: =IF('League Settings'!$B$19="Redraft",1,IF(OR(C8="DEF",C8="K",D8=0),1,IF(D8<=24,'Dynamic Adjustments'!$B$28,IF(D8<=27,'Dynamic Adjustments'!$B$29,IF(D8<=30,'Dynamic Adjustments'!$B$30,'Dynamic Adjustments'!$B$31))))) | R8: 1
A9: 6 | B9: ='Base Player Values'!B9 | C9: ='Base Player Values'!C9 | D9: ='Base Player Values'!E9 | E9: ='Base Player Values'!F9 | F9: =IFERROR(VLOOKUP(C9,'Dynamic Adjustments'!$A$18:$B$23,2,FALSE),1) | G9: =IF(OR(C9="DEF",C9="K",D9=0),1,IF(D9<=24,'Dynamic Adjustments'!$B$28,IF(D9<=27,'Dynamic Adjustments'!$B$29,IF(D9<=30,'Dynamic Adjustments'!$B$30,'Dynamic Adjustments'!$B$31)))) | H9: 1 | I9: 1 | J9: 1 | K9: 1 | L9: =E9*('Dynamic Adjustments'!$B$5*F9+'Dynamic Adjustments'!$B$6*Q9+'Dynamic Adjustments'!$B$7*H9+'Dynamic Adjustments'!$B$8*I9+'Dynamic Adjustments'!$B$9*J9+'Dynamic Adjustments'!$B$10*K9) | M9: =P9*'League Settings'!$B$7 | N9: =(L9+M9)*R9 | O9: =IF(N9>=85,"Elite",IF(N9>=70,"Star",IF(N9>=55,"Starter",IF(N9>=40,"Flex",IF(N9>=25,"Bench","Waiver"))))) | P9: =IF(C9="WR",1,IF(C9="TE",0.8,IF(C9="RB",0.5,0))) | Q9: =IF('League Settings'!$B$19="Redraft",1,IF(OR(C9="DEF",C9="K",D9=0),1,IF(D9<=24,'Dynamic Adjustments'!$B$28,IF(D9<=27,'Dynamic Adjustments'!$B$29,IF(D9<=30,'Dynamic Adjustments'!$B$30,'Dynamic Adjustments'!$B$31))))) | R9: 1
A10: 7 | B10: ='Base Player Values'!B10 | C10: ='Base Player Values'!C10 | D10: ='Base Player Values'!E10 | E10: ='Base Player Values'!F10 | F10: =IFERROR(VLOOKUP(C10,'Dynamic Adjustments'!$A$18:$B$23,2,FALSE),1) | G10: =IF(OR(C10="DEF",C10="K",D10=0),1,IF(D10<=24,'Dynamic Adjustments'!$B$28,IF(D10<=27,'Dynamic Adjustments'!$B$29,IF(D10<=30,'Dynamic Adjustments'!$B$30,'Dynamic Adjustments'!$B$31)))) | H10: 1 | I10: 1 | J10: 1 | K10: 1 | L10: =E10*('Dynamic Adjustments'!$B$5*F10+'Dynamic Adjustments'!$B$6*Q10+'Dynamic Adjustments'!$B$7*H10+'Dynamic Adjustments'!$B$8*I10+'Dynamic Adjustments'!$B$9*J10+'Dynamic Adjustments'!$B$10*K10) | M10: =P10*'League Settings'!$B$7 | N10: =(L10+M10)*R10 | O10: =IF(N10>=85,"Elite",IF(N10>=70,"Star",IF(N10>=55,"Starter",IF(N10>=40,"Flex",IF(N10>=25,"Bench","Waiver"))))) | P10: =IF(C10="WR",1,IF(C10="TE",0.8,IF(C10="RB",0.5,0))) | Q10: =IF('League Settings'!$B$19="Redraft",1,IF(OR(C10="DEF",C10="K",D10=0),1,IF(D10<=24,'Dynamic Adjustments'!$B$28,IF(D10<=27,'Dynamic Adjustments'!$B$29,IF(D10<=30,'Dynamic Adjustments'!$B$30,'Dynamic Adjustments'!$B$31))))) | R10: 1
A11: 8 | B11: ='Base Player Values'!B11 | C11: ='Base Player Values'!C11 | D11: ='Base Player Values'!E11 | E11: ='Base Player Values'!F11 | F11: =IFERROR(VLOOKUP(C11,'Dynamic Adjustments'!$A$18:$B$23,2,FALSE),1) | G11: =IF(OR(C11="DEF",C11="K",D11=0),1,IF(D11<=24,'Dynamic Adjustments'!$B$28,IF(D11<=27,'Dynamic Adjustments'!$B$29,IF(D11<=30,'Dynamic Adjustments'!$B$30,'Dynamic Adjustments'!$B$31)))) | H11: 1 | I11: 1 | J11: 1 | K11: 1 | L11: =E11*('Dynamic Adjustments'!$B$5*F11+'Dynamic Adjustments'!$B$6*Q11+'Dynamic Adjustments'!$B$7*H11+'Dynamic Adjustments'!$B$8*I11+'Dynamic Adjustments'!$B$9*J11+'Dynamic Adjustments'!$B$10*K11) | M11: =P11*'League Settings'!$B$7 | N11: =(L11+M11)*R11 | O11: =IF(N11>=85,"Elite",IF(N11>=70,"Star",IF(N11>=55,"Starter",IF(N11>=40,"Flex",IF(N11>=25,"Bench","Waiver"))))) | P11: =IF(C11="WR",1,IF(C11="TE",0.8,IF(C11="RB",0.5,0))) | Q11: =IF('League Settings'!$B$19="Redraft",1,IF(OR(C11="DEF",C11="K",D11=0),1,IF(D11<=24,'Dynamic Adjustments'!$B$28,IF(D11<=27,'Dynamic Adjustments'!$B$29,IF(D11<=30,'Dynamic Adjustments'!$B$30,'Dynamic Adjustments'!$B$31))))) | R11: 1
A12: 9 | B12: ='Base Player Values'!B12 | C12: ='Base Player Values'!C12 | D12: ='Base Player Values'!E12 | E12: ='Base Player Values'!F12 | F12: =IFERROR(VLOOKUP(C12,'Dynamic Adjustments'!$A$18:$B$23,2,FALSE),1) | G12: =IF(OR(C12="DEF",C12="K",D12=0),1,IF(D12<=24,'Dynamic Adjustments'!$B$28,IF(D12<=27,'Dynamic Adjustments'!$B$29,IF(D12<=30,'Dynamic Adjustments'!$B$30,'Dynamic Adjustments'!$B$31)))) | H12: 1 | I12: 1 | J12: 1 | K12: 1 | L12: =E12*('Dynamic Adjustments'!$B$5*F12+'Dynamic Adjustments'!$B$6*Q12+'Dynamic Adjustments'!$B$7*H12+'Dynamic Adjustments'!$B$8*I12+'Dynamic Adjustments'!$B$9*J12+'Dynamic Adjustments'!$B$10*K12) | M12: =P12*'League Settings'!$B$7 | N12: =(L12+M12)*R12 | O12: =IF(N12>=85,"Elite",IF(N12>=70,"Star",IF(N12>=55,"Starter",IF(N12>=40,"Flex",IF(N12>=25,"Bench","Waiver"))))) | P12: =IF(C12="WR",1,IF(C12="TE",0.8,IF(C12="RB",0.5,0))) | Q12: =IF('League Settings'!$B$19="Redraft",1,IF(OR(C12="DEF",C12="K",D12=0),1,IF(D12<=24,'Dynamic Adjustments'!$B$28,IF(D12<=27,'Dynamic Adjustments'!$B$29,IF(D12<=30,'Dynamic Adjustments'!$B$30,'Dynamic Adjustments'!$B$31))))) | R12: 1
A13: 10 | B13: ='Base Player Values'!B13 | C13: ='Base Player Values'!C13 | D13: ='Base Player Values'!E13 | E13: ='Base Player Values'!F13 | F13: =IFERROR(VLOOKUP(C13,'Dynamic Adjustments'!$A$18:$B$23,2,FALSE),1) | G13: =IF(OR(C13="DEF",C13="K",D13=0),1,IF(D13<=24,'Dynamic Adjustments'!$B$28,IF(D13<=27,'Dynamic Adjustments'!$B$29,IF(D13<=30,'Dynamic Adjustments'!$B$30,'Dynamic Adjustments'!$B$31)))) | H13: 1 | I13: 1 | J13: 1 | K13: 1 | L13: =E13*('Dynamic Adjustments'!$B$5*F13+'Dynamic Adjustments'!$B$6*Q13+'Dynamic Adjustments'!$B$7*H13+'Dynamic Adjustments'!$B$8*I13+'Dynamic Adjustments'!$B$9*J13+'Dynamic Adjustments'!$B$10*K13) | M13: =P13*'League Settings'!$B$7 | N13: =(L13+M13)*R13 | O13: =IF(N13>=85,"Elite",IF(N13>=70,"Star",IF(N13>=55,"Starter",IF(N13>=40,"Flex",IF(N13>=25,"Bench","Waiver"))))) | P13: =IF(C13="WR",1,IF(C13="TE",0.8,IF(C13="RB",0.5,0))) | Q13: =IF('League Settings'!$B$19="Redraft",1,IF(OR(C13="DEF",C13="K",D13=0),1,IF(D13<=24,'Dynamic Adjustments'!$B$28,IF(D13<=27,'Dynamic Adjustments'!$B$29,IF(D13<=30,'Dynamic Adjustments'!$B$30,'Dynamic Adjustments'!$B$31))))) | R13: 1
A14: 11 | B14: ='Base Player Values'!B14 | C14: ='Base Player Values'!C14 | D14: ='Base Player Values'!E14 | E14: ='Base Player Values'!F14 | F14: =IFERROR(VLOOKUP(C14,'Dynamic Adjustments'!$A$18:$B$23,2,FALSE),1) | G14: =IF(OR(C14="DEF",C14="K",D14=0),1,IF(D14<=24,'Dynamic Adjustments'!$B$28,IF(D14<=27,'Dynamic Adjustments'!$B$29,IF(D14<=30,'Dynamic Adjustments'!$B$30,'Dynamic Adjustments'!$B$31)))) | H14: 1 | I14: 1 | J14: 1 | K14: 1 | L14: =E14*('Dynamic Adjustments'!$B$5*F14+'Dynamic Adjustments'!$B$6*Q14+'Dynamic Adjustments'!$B$7*H14+'Dynamic Adjustments'!$B$8*I14+'Dynamic Adjustments'!$B$9*J14+'Dynamic Adjustments'!$B$10*K14) | M14: =P14*'League Settings'!$B$7 | N14: =(L14+M14)*R14 | O14: =IF(N14>=85,"Elite",IF(N14>=70,"Star",IF(N14>=55,"Starter",IF(N14>=40,"Flex",IF(N14>=25,"Bench","Waiver"))))) | P14: =IF(C14="WR",1,IF(C14="TE",0.8,IF(C14="RB",0.5,0))) | Q14: =IF('League Settings'!$B$19="Redraft",1,IF(OR(C14="DEF",C14="K",D14=0),1,IF(D14<=24,'Dynamic Adjustments'!$B$28,IF(D14<=27,'Dynamic Adjustments'!$B$29,IF(D14<=30,'Dynamic Adjustments'!$B$30,'Dynamic Adjustments'!$B$31))))) | R14: 1
A15: 12 | B15: ='Base Player Values'!B15 | C15: ='Base Player Values'!C15 | D15: ='Base Player Values'!E15 | E15: ='Base Player Values'!F15 | F15: =IFERROR(VLOOKUP(C15,'Dynamic Adjustments'!$A$18:$B$23,2,FALSE),1) | G15: =IF(OR(C15="DEF",C15="K",D15=0),1,IF(D15<=24,'Dynamic Adjustments'!$B$28,IF(D15<=27,'Dynamic Adjustments'!$B$29,IF(D15<=30,'Dynamic Adjustments'!$B$30,'Dynamic Adjustments'!$B$31)))) | H15: 1 | I15: 1 | J15: 1 | K15: 1 | L15: =E15*('Dynamic Adjustments'!$B$5*F15+'Dynamic Adjustments'!$B$6*Q15+'Dynamic Adjustments'!$B$7*H15+'Dynamic Adjustments'!$B$8*I15+'Dynamic Adjustments'!$B$9*J15+'Dynamic Adjustments'!$B$10*K15) | M15: =P15*'League Settings'!$B$7 | N15: =(L15+M15)*R15 | O15: =IF(N15>=85,"Elite",IF(N15>=70,"Star",IF(N15>=55,"Starter",IF(N15>=40,"Flex",IF(N15>=25,"Bench","Waiver"))))) | P15: =IF(C15="WR",1,IF(C15="TE",0.8,IF(C15="RB",0.5,0))) | Q15: =IF('League Settings'!$B$19="Redraft",1,IF(OR(C15="DEF",C15="K",D15=0),1,IF(D15<=24,'Dynamic Adjustments'!$B$28,IF(D15<=27,'Dynamic Adjustments'!$B$29,IF(D15<=30,'Dynamic Adjustments'!$B$30,'Dynamic Adjustments'!$B$31))))) | R15: 1
... A63: 60 | B63: ='Base Player Values'!B63 | C63: ='Base Player Values'!C63 | D63: ='Base Player Values'!E63 | E63: ='Base Player Values'!F63 | F63: =IFERROR(VLOOKUP(C63,'Dynamic Adjustments'!$A$18:$B$23,2,FALSE),1) | G63: =IF(OR(C63="DEF",C63="K",D63=0),1,IF(D63<=24,'Dynamic Adjustments'!$B$28,IF(D63<=27,'Dynamic Adjustments'!$B$29,IF(D63<=30,'Dynamic Adjustments'!$B$30,'Dynamic Adjustments'!$B$31)))) | H63: 1 | I63: 1 | J63: 1 | K63: 1 | L63: =E63*('Dynamic Adjustments'!$B$5*F63+'Dynamic Adjustments'!$B$6*Q63+'Dynamic Adjustments'!$B$7*H63+'Dynamic Adjustments'!$B$8*I63+'Dynamic Adjustments'!$B$9*J63+'Dynamic Adjustments'!$B$10*K63) | M63: =P63*'League Settings'!$B$7 | N63: =(L63+M63)*R63 | O63: =IF(N63>=85,"Elite",IF(N63>=70,"Star",IF(N63>=55,"Starter",IF(N63>=40,"Flex",IF(N63>=25,"Bench","Waiver"))))) | P63: =IF(C63="WR",1,IF(C63="TE",0.8,IF(C63="RB",0.5,0))) | Q63: =IF('League Settings'!$B$19="Redraft",1,IF(OR(C63="DEF",C63="K",D63=0),1,IF(D63<=24,'Dynamic Adjustments'!$B$28,IF(D63<=27,'Dynamic Adjustments'!$B$29,IF(D63<=30,'Dynamic Adjustments'!$B$30,'Dynamic Adjustments'!$B$31))))) | R63: 1

Sheet Trade Calculator
A1: Trade Calculator
A2: Evaluate Trades Up to 5 vs 5 Players — Automatic Trade Scores & Verdicts
A4: TEAM A GIVES | H4: TEAM B GIVES
A5: # | B5: Player Name | C5: Position | D5: Final Adj DTV | E5: DTV Tier | H5: # | I5: Player Name | J5: Position | K5: Final Adj DTV | L5: DTV Tier
A6: 1 | C6: =IF(B6="","",IFERROR(INDEX('Dynamic Trade Chart'!C$4:C$64,MATCH(B6,'Dynamic Trade Chart'!B$4:B$64,0)),"Not Found")) | D6: =IF(B6="",0,IFERROR(INDEX('Dynamic Trade Chart'!N$4:N$64,MATCH(B6,'Dynamic Trade Chart'!B$4:B$64,0)),0)) | E6: =IF(B6="","",IFERROR(INDEX('Dynamic Trade Chart'!O$4:O$64,MATCH(B6,'Dynamic Trade Chart'!B$4:B$64,0)),"")) | H6: 1 | J6: =IF(I6="","",IFERROR(INDEX('Dynamic Trade Chart'!C$4:C$64,MATCH(I6,'Dynamic Trade Chart'!B$4:B$64,0)),"Not Found")) | K6: =IF(I6="",0,IFERROR(INDEX('Dynamic Trade Chart'!N$4:N$64,MATCH(I6,'Dynamic Trade Chart'!B$4:B$64,0)),0)) | L6: =IF(I6="","",IFERROR(INDEX('Dynamic Trade Chart'!O$4:O$64,MATCH(I6,'Dynamic Trade Chart'!B$4:B$64,0)),""))
A7: 2 | C7: =IF(B7="","",IFERROR(INDEX('Dynamic Trade Chart'!C$4:C$64,MATCH(B7,'Dynamic Trade Chart'!B$4:B$64,0)),"Not Found")) | D7: =IF(B7="",0,IFERROR(INDEX('Dynamic Trade Chart'!N$4:N$64,MATCH(B7,'Dynamic Trade Chart'!B$4:B$64,0)),0)) | E7: =IF(B7="","",IFERROR(INDEX('Dynamic Trade Chart'!O$4:O$64,MATCH(B7,'Dynamic Trade Chart'!B$4:B$64,0)),"")) | H7: 2 | J7: =IF(I7="","",IFERROR(INDEX('Dynamic Trade Chart'!C$4:C$64,MATCH(I7,'Dynamic Trade Chart'!B$4:B$64,0)),"Not Found")) | K7: =IF(I7="",0,IFERROR(INDEX('Dynamic Trade Chart'!N$4:N$64,MATCH(I7,'Dynamic Trade Chart'!B$4:B$64,0)),0)) | L7: =IF(I7="","",IFERROR(INDEX('Dynamic Trade Chart'!O$4:O$64,MATCH(I7,'Dynamic Trade Chart'!B$4:B$64,0)),""))
A8: 3 | C8: =IF(B8="","",IFERROR(INDEX('Dynamic Trade Chart'!C$4:C$64,MATCH(B8,'Dynamic Trade Chart'!B$4:B$64,0)),"Not Found")) | D8: =IF(B8="",0,IFERROR(INDEX('Dynamic Trade Chart'!N$4:N$64,MATCH(B8,'Dynamic Trade Chart'!B$4:B$64,0)),0)) | E8: =IF(B8="","",IFERROR(INDEX('Dynamic Trade Chart'!O$4:O$64,MATCH(B8,'Dynamic Trade Chart'!B$4:B$64,0)),"")) | H8: 3 | J8: =IF(I8="","",IFERROR(INDEX('Dynamic Trade Chart'!C$4:C$64,MATCH(I8,'Dynamic Trade Chart'!B$4:B$64,0)),"Not Found")) | K8: =IF(I8="",0,IFERROR(INDEX('Dynamic Trade Chart'!N$4:N$64,MATCH(I8,'Dynamic Trade Chart'!B$4:B$64,0)),0)) | L8: =IF(I8="","",IFERROR(INDEX('Dynamic Trade Chart'!O$4:O$64,MATCH(I8,'Dynamic Trade Chart'!B$4:B$64,0)),""))
A9: 4 | C9: =IF(B9="","",IFERROR(INDEX('Dynamic Trade Chart'!C$4:C$64,MATCH(B9,'Dynamic Trade Chart'!B$4:B$64,0)),"Not Found")) | D9: =IF(B9="",0,IFERROR(INDEX('Dynamic Trade Chart'!N$4:N$64,MATCH(B9,'Dynamic Trade Chart'!B$4:B$64,0)),0)) | E9: =IF(B9="","",IFERROR(INDEX('Dynamic Trade Chart'!O$4:O$64,MATCH(B9,'Dynamic Trade Chart'!B$4:B$64,0)),"")) | H9: 4 | J9: =IF(I9="","",IFERROR(INDEX('Dynamic Trade Chart'!C$4:C$64,MATCH(I9,'Dynamic Trade Chart'!B$4:B$64,0)),"Not Found")) | K9: =IF(I9="",0,IFERROR(INDEX('Dynamic Trade Chart'!N$4:N$64,MATCH(I9,'Dynamic Trade Chart'!B$4:B$64,0)),0)) | L9: =IF(I9="","",IFERROR(INDEX('Dynamic Trade Chart'!O$4:O$64,MATCH(I9,'Dynamic Trade Chart'!B$4:B$64,0)),""))
A10: 5 | C10: =IF(B10="","",IFERROR(INDEX('Dynamic Trade Chart'!C$4:C$64,MATCH(B10,'Dynamic Trade Chart'!B$4:B$64,0)),"Not Found")) | D10: =IF(B10="",0,IFERROR(INDEX('Dynamic Trade Chart'!N$4:N$64,MATCH(B10,'Dynamic Trade Chart'!B$4:B$64,0)),0)) | E10: =IF(B10="","",IFERROR(INDEX('Dynamic Trade Chart'!O$4:O$64,MATCH(B10,'Dynamic Trade Chart'!B$4:B$64,0)),"")) | H10: 5 | J10: =IF(I10="","",IFERROR(INDEX('Dynamic Trade Chart'!C$4:C$64,MATCH(I10,'Dynamic Trade Chart'!B$4:B$64,0)),"Not Found")) | K10: =IF(I10="",0,IFERROR(INDEX('Dynamic Trade Chart'!N$4:N$64,MATCH(I10,'Dynamic Trade Chart'!B$4:B$64,0)),0)) | L10: =IF(I10="","",IFERROR(INDEX('Dynamic Trade Chart'!O$4:O$64,MATCH(I10,'Dynamic Trade Chart'!B$4:B$64,0)),""))
A12: Team A Total DTV | C12: =IF(COUNTA(B6:B10)=0,0,SUM(D6:D10)) | H12: Team B Total DTV | J12: =IF(COUNTA(I6:I10)=0,0,SUM(K6:K10))
A15: TRADE ANALYSIS
A17: Trade Differential | D17: =C12-J12
A19: Trade Score | D19: =IF(AND(C12=0,J12=0),"—",MIN(100,MAX(0,50+D17*1.67)))
A21: Verdict | D21: =IF(AND(C12=0,J12=0),"Enter players above to evaluate a trade",IF(D19>=90,"Slam Dunk",IF(D19>=75,"Strong Win",IF(D19>=60,"Slight Edge",IF(D19>=45,"Fair Trade",IF(D19>=30,"Slight Loss",IF(D19>=15,"Bad Deal","Robbery")))))))
A23: TRADE SCORE: 0-100 Scale | 90-100 Slam Dunk | 75-89 Strong Win | 60-74 Slight Edge | 45-59 Fair Trade | 30-44 Slight Loss | 15-29 Bad Deal | 0-14 Robbery
